Workbook

Sheet Dashboard
I6: Britannia Industries is one of the Indias leading food companies | S6: with 100 year of legacy and annual revenues in | AA6: excess of Rs. 16000 Cr. Britannia is among the most trusted food brands,
I7: and manufacturers Indias favourite brands like Good Day, Tiger, Nutrichoice | U7: ,Milk Bikis and Marie Gold and many more . Britannia's product portfolio includes Biscuits , Bread , Cakes , Rusk,
S8: and dairy products inlcluding Cheese , Beverages ,Milk and Yogurt.
J10: Company Registered Name : Britannia Industries Limited | U10: Sector: FMCG | Y10: TICKER: BRITANNIA | AD10: BSE CODE: 500825 | AI10: CMP: 6106

Sheet About
B10: Peer companies
E12: Name of Company | L12: Country | O12: CMP | R12: Market Capital | U12: Revenue Growth (%) | AA12: Profit Growth (%)
E14: Nestle India | L14: India | O14: 1293.8 | R14: 249485.31 | W14: 9.74 | AB14: 1.34
E15: Bikaji Foods | L15: India | O15: 635.35 | R15: 15921.41 | W15: 9.98 | AB15: -8.31
E16: Zydus Wellness | L16: India | O16: 52.83 | R16: 12702.57 | W16: 31.45 | AB16: -24.89
E17: Gopal Snacks | L17: India | O17: 311.55 | R17: 3882.61 | W17: -6.17 | AB17: -58.17
E18: Mrs Bectors | L18: India | O18: 216.65 | R18: 6650.95 | W18: 8.93 | AB18: -4.06
B21: Shareholding pattern
E23: Investors | M23: 2025 | S23: Major Shareholders
E24: Shareholders | J24: March | L24: June | N24: Septemer | P24: December
E26: Promoters | J26: 0.5055 | L26: 0.5055 | N26: 0.5055 | P26: 0.5055 | R26: Promoters | S26: Associated Biscuits International Limited
E27: FIIs | J27: 0.1572 | L27: 0.1558 | N27: 0.1502 | P27: 0.1488 | R27: FIIs | S27: J P Morgan Funds
E28: DIIs | J28: 0.1826 | L28: 0.1865 | N28: 0.1939 | P28: 0.1955 | R28: DIIs | S28: Lici New Endowment Plus-Secured Fund
E29: Government | J29: 0 | L29: 0.0001 | N29: 0.0001 | P29: 0.0003
E30: Public | J30: 0.1548 | L30: 0.152 | N30: 0.1503 | P30: 0.1497
B34: Recent Updates
E36: Financial Performance: Q3 FY26 net profit rose 17% to ₹680 crore, with revenue increasing 9.5%.
E38: Leadership Change: Rakshit Hargave was appointed CEO and MD to drive growth.
E40: Strategic Focus: Adopting a "startup mentality" to unlock "resident jewels" (smaller brands) to boost margins.
E42: Stock Trend: As of Feb 20, 2026, the stock has experienced a minor, temporary downward trend (down -0.17% to ₹6,098.50) following recent highs.
E44: Input Costs: Operating with, softened input costs, boosting margins.
E46: Growth Strategy: Focus on urban consumption, which is showing signs of recovery after being dull.
E48: Market Position: Remains a top FMCG pick with a market cap of over ₹1,46,000

Sheet Balance Sheet
B1: Britannia Industries Limited
B2: BALANCE SHEET
B4: Particulars | C4: 2019 | D4: 2020 | E4: 2021 | F4: 2022 | G4: 2023 | H4: 2024 | I4: 2025 | J4: 2026 | K4: 2027 | L4: 2028 | M4: 2029 | N4: 2030 | O4: 2031 | P4: 2032
C5: Actual | D5: Actual | E5: Actual | F5: Actual | G5: Actual | H5: Actual | I5: Actual | J5: Forecast | K5: Forecast | L5: Forecast | M5: Forecast | N5: Forecast | O5: Forecast | P5: Forecast
A6: I | B6: ASSETS
A7: 1 | B7: Non-current assets
B8: (a) Property, plant and equipment | C8: 1535.58 | D8: 1716.37 | E8: 1634.3 | F8: 1584.05 | G8: 2472.19 | H8: 2602.94 | I8: 2734.61 | J8: ='Asset Schedule'!J40 -> 2493.7754 | K8: ='Asset Schedule'!K40 -> 2426.4029 | L8: ='Asset Schedule'!L40 -> 2404.0222 | M8: ='Asset Schedule'!M40 -> 2435.9469 | N8: ='Asset Schedule'!N40 -> 2529.5293 | O8: ='Asset Schedule'!O40 -> 2686.1088 | P8: ='Asset Schedule'!P40 -> 2918.4263
B9: (b) Capital work-in-progress | C9: 101.24 | D9: 39.55 | E9: 116.52 | F9: 535.68 | G9: 105 | H9: 187.54 | I9: 89.2 | J9: ='Asset Schedule'!J41 -> 209.85024 | K9: ='Asset Schedule'!K41 -> 204.18087 | L9: ='Asset Schedule'!L41 -> 202.29755 | M9: ='Asset Schedule'!M41 -> 204.984 | N9: ='Asset Schedule'!N41 -> 212.85892 | O9: ='Asset Schedule'!O41 -> 226.03502 | P9: ='Asset Schedule'!P41 -> 245.58446
B10: (c) Investment property | C10: 14.73 | D10: 14.47 | E10: 14.21 | F10: 13.95 | G10: 40.63 | H10: 27.48 | I10: 28.9 | J10: ='Asset Schedule'!J42 -> 26.162712 | K10: ='Asset Schedule'!K42 -> 25.455893 | L10: ='Asset Schedule'!L42 -> 25.221093 | M10: ='Asset Schedule'!M42 -> 25.556022 | N10: ='Asset Schedule'!N42 -> 26.537814 | O10: ='Asset Schedule'!O42 -> 28.180522 | P10: ='Asset Schedule'!P42 -> 30.617813
B11: (d) Goodwill | C11: 130.37 | D11: 138.97 | E11: 135.9 | F11: 139.61 | G11: 128.16 | H11: 129.82 | I11: 132.78 | J11: =I11 -> 132.78 | K11: =J11 -> 132.78 | L11: =K11 -> 132.78 | M11: =L11 -> 132.78 | N11: =M11 -> 132.78 | O11: =N11 -> 132.78 | P11: =O11 -> 132.78
B12: (e) Other intangible assets | C12: 7.62 | D12: 8.37 | E12: 8.54 | F12: 15.6 | G12: 14.24 | H12: 10.9 | I12: 7.51 | J12: ='Asset Schedule'!J43 -> 13.032553 | K12: ='Asset Schedule'!K43 -> 12.680462 | L12: ='Asset Schedule'!L43 -> 12.5635 | M12: ='Asset Schedule'!M43 -> 12.730339 | N12: ='Asset Schedule'!N43 -> 13.219404 | O12: ='Asset Schedule'!O43 -> 14.037693 | P12: ='Asset Schedule'!P43 -> 15.251793
B13: (f) Investment in associates | C13: 1.04 | D13: 1.48 | E13: 2.29 | F13: 2.09 | G13: 495.16 | H13: 491.96 | I13: 483.62 | J13: =I13 -> 483.62 | K13: =J13 -> 483.62 | L13: =K13 -> 483.62 | M13: =L13 -> 483.62 | N13: =M13 -> 483.62 | O13: =N13 -> 483.62 | P13: =O13 -> 483.62
B14: (g) Financial assets
B15: (i) Investments | C15: 725.36 | D15: 1882.98 | E15: 1385.15 | F15: 926.55 | G15: 1028.09 | H15: 578.25 | I15: 1270.17 | J15: =I15 -> 1270.17 | K15: =J15 -> 1270.17 | L15: =K15 -> 1270.17 | M15: =L15 -> 1270.17 | N15: =M15 -> 1270.17 | O15: =N15 -> 1270.17 | P15: =O15 -> 1270.17
B16: (ii) Loans receivable | C16: 19.02 | D16: 202.95 | E16: 74.58 | F16: 100 | G16: 150 | H16: 0 | I16: 25 | J16: =I16 -> 25 | K16: =J16 -> 25 | L16: =K16 -> 25 | M16: =L16 -> 25 | N16: =M16 -> 25 | O16: =N16 -> 25 | P16: =O16 -> 25
B17: (iii) Other financial assets | C17: 28.67 | D17: 31.33 | E17: 30.13 | F17: 31.8 | G17: 23.57 | H17: 25.5 | I17: 28.19 | J17: =I17 -> 28.19 | K17: =J17 -> 28.19 | L17: =K17 -> 28.19 | M17: =L17 -> 28.19 | N17: =M17 -> 28.19 | O17: =N17 -> 28.19 | P17: =O17 -> 28.19
B18: (h) Deferred tax assets, (net) | C18: 13.75 | D18: 19.56 | E18: 9.66 | F18: 51.67 | G18: 57.25 | H18: 43.88 | I18: 36.59 | J18: =I18 -> 36.59 | K18: =J18 -> 36.59 | L18: =K18 -> 36.59 | M18: =L18 -> 36.59 | N18: =M18 -> 36.59 | O18: =N18 -> 36.59 | P18: =O18 -> 36.59
B19: (i) Income-tax assets, (net) | C19: 37.02 | D19: 68.77 | E19: 71.84 | F19: 44.93 | G19: 43.64 | H19: 67.95 | I19: 46.26 | J19: =I19 -> 46.26 | K19: =J19 -> 46.26 | L19: =K19 -> 46.26 | M19: =L19 -> 46.26 | N19: =M19 -> 46.26 | O19: =N19 -> 46.26 | P19: =O19 -> 46.26
B20: (j) Other non-current assets | C20: 101.08 | D20: 42.46 | E20: 105.98 | F20: 99.18 | G20: 48.56 | H20: 58.68 | I20: 42.04 | J20: =I20 -> 42.04 | K20: =J20 -> 42.04 | L20: =K20 -> 42.04 | M20: =L20 -> 42.04 | N20: =M20 -> 42.04 | O20: =N20 -> 42.04 | P20: =O20 -> 42.04
B21: Total non-current assets | C21: =SUM(C8:C20) -> 2715.48 | D21: =SUM(D8:D20) -> 4167.26 | E21: =SUM(E8:E20) -> 3589.1 | F21: =SUM(F8:F20) -> 3545.11 | G21: =SUM(G8:G20) -> 4606.49 | H21: =SUM(H8:H20) -> 4224.9 | I21: =SUM(I8:I20) -> 4924.87 | J21: =SUM(J8:J20) -> 4807.4709 | ... P21: =SUM(P8:P20) -> 5274.5304
A23: 2 | B23: Current assets
B24: (a) Inventories | C24: 781.38 | D24: 740.96 | E24: 1091.49 | F24: 1367.49 | G24: 1193.26 | H24: 1181.22 | I24: 1236.51 | J24: ='Working Capital Schedule'!J11 -> 1527.6793 | K24: ='Working Capital Schedule'!K11 -> 1626.7369 | L24: ='Working Capital Schedule'!L11 -> 1673.1872 | M24: ='Working Capital Schedule'!M11 -> 2030.8365 | N24: ='Working Capital Schedule'!N11 -> 2250.8721 | O24: ='Working Capital Schedule'!O11 -> 2470.0177 | P24: ='Working Capital Schedule'!P11 -> 2783.9632
B25: (b) Financial assets
B26: (i) Investments | C26: 749.88 | D26: 1008.77 | E26: 1393.25 | F26: 833.73 | G26: 1800.99 | H26: 1696.51 | I26: 1111.64 | J26: =I26 -> 1111.64 | K26: =J26 -> 1111.64 | L26: =K26 -> 1111.64 | M26: =L26 -> 1111.64 | N26: =M26 -> 1111.64 | O26: =N26 -> 1111.64 | P26: =O26 -> 1111.64
B27: (ii) Trade receivables | C27: 394.24 | D27: 320.36 | E27: 257.27 | F27: 331.93 | G27: 328.94 | H27: 393.33 | I27: 448.61 | J27: ='Working Capital Schedule'!J24 -> 428.67911 | K27: ='Working Capital Schedule'!K24 -> 522.88797 | L27: ='Working Capital Schedule'!L24 -> 517.30271 | M27: ='Working Capital Schedule'!M24 -> 629.45323 | N27: ='Working Capital Schedule'!N24 -> 646.5336 | O27: ='Working Capital Schedule'!O24 -> 787.62691 | P27: ='Working Capital Schedule'!P24 -> 842.09291
B28: (iii) Cash and cash equivalents | C28: 60.32 | D28: 81.23 | E28: 142.74 | F28: 117.99 | G28: 102.38 | H28: 322.8 | I28: 132.78 | J28: =CFS!J64 -> 1818.16 | K28: =CFS!K64 -> 4163.21 | L28: =CFS!L64 -> 7648.45 | M28: =CFS!M64 -> 12739.52 | N28: =CFS!N64 -> 18896.2 | O28: =CFS!O64 -> 28895.25 | P28: =CFS!P64 -> 44241.37
B29: (iv) Bank balances other than (iii) above | C29: 49.5 | D29: 41.62 | E29: 68.6 | F29: 66.91 | G29: 95.6 | H29: 123.55 | I29: 179.7 | J29: =I29 -> 179.7 | K29: =J29 -> 179.7 | L29: =K29 -> 179.7 | M29: =L29 -> 179.7 | N29: =M29 -> 179.7 | O29: =N29 -> 179.7 | P29: =O29 -> 179.7
B30: (v) Loans receivable | C30: 1203.92 | D30: 1110.11 | E30: 946.56 | F30: 698 | G30: 560 | H30: 460 | I30: 50 | J30: =I30 -> 50 | K30: =J30 -> 50 | L30: =K30 -> 50 | M30: =L30 -> 50 | N30: =M30 -> 50 | O30: =N30 -> 50 | P30: =O30 -> 50
B31: (vi) Other financial assets | C31: 126.29 | D31: 229.75 | E31: 397.76 | F31: 428.03 | G31: 451.96 | H31: 531.13 | I31: 630.46 | J31: =I31 -> 630.46 | K31: =J31 -> 630.46 | L31: =K31 -> 630.46 | M31: =L31 -> 630.46 | N31: =M31 -> 630.46 | O31: =N31 -> 630.46 | P31: =O31 -> 630.46
B32: (c) Other current assets | C32: 160.81 | D32: 142.17 | E32: 122.01 | F32: 138.22 | G32: 180.74 | H32: 133.71 | I32: 123.98 | J32: =I32 -> 123.98 | K32: =J32 -> 123.98 | L32: =K32 -> 123.98 | M32: =L32 -> 123.98 | N32: =M32 -> 123.98 | O32: =N32 -> 123.98 | P32: =O32 -> 123.98
B33: (d) Assets held for sale | E33: 0 | F33: 0 | G33: 32.36 | H33: 6.41 | I33: 0 | J33: =I33 -> 0 | K33: =J33 -> 0 | L33: =K33 -> 0 | M33: =L33 -> 0 | N33: =M33 -> 0 | O33: =N33 -> 0 | P33: =O33 -> 0
B34: Total current assets | C34: =SUM(C24:C32) -> 3526.34 | D34: =SUM(D24:D32) -> 3674.97 | E34: =SUM(E24:E33) -> 4419.68 | F34: =SUM(F24:F33) -> 3982.3 | G34: =SUM(G24:G33) -> 4746.23 | H34: =SUM(H24:H33) -> 4848.66 | I34: =SUM(I24:I33) -> 3913.68 | J34: =SUM(J24:J32) -> 5870.2984 | K34: =SUM(K24:K32) -> 8408.6148 | L34: =SUM(L24:L32) -> 11934.72 | M34: =SUM(M24:M32) -> 17495.59 | N34: =SUM(N24:N32) -> 23889.386 | O34: =SUM(O24:O32) -> 34248.675 | P34: =SUM(P24:P32) -> 49963.206
B36: Total Assets (I) | C36: =SUM(C21+C34) -> 6241.82 | D36: =SUM(D21+D34) -> 7842.23 | E36: =SUM(E21+E34) -> 8008.78 | F36: =SUM(F21+F34) -> 7527.41 | G36: =SUM(G21+G34) -> 9352.72 | H36: =SUM(H21+H34) -> 9073.56 | I36: =SUM(I21+I34) -> 8838.55 | J36: =SUM(J21+J34) -> 10677.769 | ... P36: =SUM(P21+P34) -> 55237.737
A38: II | B38: EQUITY AND LIABILITIES
A39: A | B39: Equity Shareholde's fund
B40: (a) Equity share capital | C40: 24.03 | D40: 24.05 | E40: 24.09 | F40: 24.09 | G40: 24.09 | H40: 24.09 | I40: 24.09 | J40: =I40 -> 24.09 | K40: =J40 -> 24.09 | L40: =K40 -> 24.09 | M40: =L40 -> 24.09 | N40: =M40 -> 24.09 | O40: =N40 -> 24.09 | P40: =O40 -> 24.09
B41: (b) Reserves and Surplus | C41: 4229.22 | D41: 4378.78 | E41: 3523.57 | F41: 2534.01 | G41: 3510.18 | H41: 3917.43 | I41: 4331.63 | J41: =I41+'Income Statement'!J38+CFS!J57 -> 5405.9743 | K41: =J41+'Income Statement'!K38+CFS!K57 -> 6631.9513 | L41: =K41+'Income Statement'!L38+CFS!L57 -> 8919.9366 | M41: =L41+'Income Statement'!M38+CFS!M57 -> 11633.993 | N41: =M41+'Income Statement'!N38+CFS!N57 -> 14673.31 | O41: =N41+'Income Statement'!O38+CFS!O57 -> 19129.339 | P41: =O41+'Income Statement'!P38+CFS!P57 -> 25858.743
B42: Total share capital | C42: =SUM(C40:C41) -> 4253.25 | D42: =SUM(D40:D41) -> 4402.83 | E42: =SUM(E40:E41) -> 3547.66 | F42: =SUM(F40:F41) -> 2558.1 | G42: =SUM(G40:G41) -> 3534.27 | H42: =SUM(H40:H41) -> 3941.52 | I42: =SUM(I40:I41) -> 4355.72 | J42: =SUM(J40:J41) -> 5430.0643 | ... P42: =SUM(P40:P41) -> 25882.833
B43: Non-controlling interests | C43: 32.68 | D43: 35.65 | E43: 36.34 | F43: 27.5 | G43: 30.23 | H43: 24.5 | I43: 25.6 | J43: =I43 -> 25.6 | K43: =J43 -> 25.6 | L43: =K43 -> 25.6 | M43: =L43 -> 25.6 | N43: =M43 -> 25.6 | O43: =N43 -> 25.6 | P43: =O43 -> 25.6
B44: Total equity | C44: =SUM(C42:C43) -> 4285.93 | D44: =SUM(D42:D43) -> 4438.48 | E44: =SUM(E42:E43) -> 3584 | F44: =SUM(F42:F43) -> 2585.6 | G44: =SUM(G42:G43) -> 3564.5 | H44: =SUM(H42:H43) -> 3966.02 | I44: =SUM(I42:I43) -> 4381.32 | J44: =SUM(J42:J43) -> 5455.6643 | ... P44: =SUM(P42:P43) -> 25908.433
...

Sheet Income Statement
B1: Britannia Industries Limited
B2: INCOME STATEMENTS
B3: (in INR Crores )
B5: Particulars | C5: 2019 | D5: 2020 | E5: 2021 | F5: 2022 | G5: 2023 | H5: 2024 | I5: 2025 | J5: 2026 | K5: 2027 | L5: 2028 | M5: 2029 | N5: 2030 | O5: 2031 | P5: 2032
C6: Actual | D6: Actual | E6: Actual | F6: Actual | G6: Actual | H6: Actual | I6: Actual | J6: Forecast | K6: Forecast | L6: Forecast | M6: Forecast | N6: Forecast | O6: Forecast | P6: Forecast
A7: I | B7: Revenue from operations: | D7: =D8/C8-1 -> 0.04287891 | E7: =E8/D8-1 -> 0.12574723 | F7: =F8/E8-1 -> 0.08240524 | G7: =G8/F8-1 -> 0.14630895 | H7: =H8/G8-1 -> 0.035115015 | I7: =I8/H8-1 -> 0.059760513 | J7: =J8/I8-1 -> 0.086167566 | K7: =K8/J8-1 -> 0.08466778 | ... P7: =P8/O8-1 -> 0.13635812
B8: Sales of goods / Income from operations | C8: 10973.46 | D8: 11443.99 | E8: 12883.04 | F8: 13944.67 | G8: 15984.9 | H8: 16546.21 | I8: 17535.02 | J8: ='Revenue Schedule'!J11 -> 19045.97 | K8: ='Revenue Schedule'!K11 -> 20658.55 | L8: ='Revenue Schedule'!L11 -> 22582.57 | M8: ='Revenue Schedule'!M11 -> 24896.1 | N8: ='Revenue Schedule'!N11 -> 27701.71 | O8: ='Revenue Schedule'!O11 -> 31135.66 | P8: ='Revenue Schedule'!P11 -> 35381.26
B9: Other operating revenues | C9: 81.21 | D9: 155.56 | E9: 253.1 | F9: 191.59 | G9: 315.65 | H9: 223.06 | I9: 407.65 | J9: ='Revenue Schedule'!J12 -> 277.75725 | K9: ='Revenue Schedule'!K12 -> 301.27104 | L9: ='Revenue Schedule'!L12 -> 329.33077 | M9: ='Revenue Schedule'!M12 -> 363.07476 | N9: ='Revenue Schedule'!N12 -> 403.98653 | O9: ='Revenue Schedule'!O12 -> 454.07058 | P9: ='Revenue Schedule'!P12 -> 515.98405
B10: Total operating revenue | C10: =SUM(C8:C9) -> 11054.67 | D10: =SUM(D8:D9) -> 11599.55 | E10: =SUM(E8:E9) -> 13136.14 | F10: =SUM(F8:F9) -> 14136.26 | G10: =SUM(G8:G9) -> 16300.55 | H10: =SUM(H8:H9) -> 16769.27 | I10: =SUM(I8:I9) -> 17942.67 | J10: =SUM(J8:J9) -> 19323.727 | ... P10: =SUM(P8:P9) -> 35897.244
A11: II | B11: Other income | C11: 206.45 | D11: 279.4 | E11: 312.87 | F11: 222.83 | G11: 215.86 | H11: 214.18 | I11: 227.09 | J11: ='Other Schedule'!J13 -> 217.3739 | K11: ='Other Schedule'!K13 -> 573.46707 | L11: ='Other Schedule'!L13 -> 1088.58 | M11: ='Other Schedule'!M13 -> 1846.3069 | N11: ='Other Schedule'!N13 -> 2840.0587 | O11: ='Other Schedule'!O13 -> 4267.4362 | P11: ='Other Schedule'!P13 -> 6506.7114
A12: III | B12: Total income (I+II) | C12: =SUM(C10:C11) -> 11261.12 | D12: =SUM(D10:D11) -> 11878.95 | E12: =SUM(E10:E11) -> 13449.01 | F12: =SUM(F10:F11) -> 14359.09 | G12: =SUM(G10:G11) -> 16516.41 | H12: =SUM(H10:H11) -> 16983.45 | I12: =SUM(I10:I11) -> 18169.76 | J12: =SUM(J10:J11) -> 19541.101 | ... P12: =SUM(P10:P11) -> 42403.955
A13: IV | B13: Expenses :
B14: Cost of material consumed | C14: 5513.01 | D14: 5901.16 | E14: 6502.33 | F14: 7473.97 | G14: 8326.7 | H14: 8546.89 | I14: 9859.45 | J14: ='Cost Schedule '!J10 -> 9791.2203 | K14: ='Cost Schedule '!K10 -> 10952.213 | L14: ='Cost Schedule '!L10 -> 11373.628 | M14: ='Cost Schedule '!M10 -> 12978.79 | N14: ='Cost Schedule '!N10 -> 15175.712 | O14: ='Cost Schedule '!O10 -> 16781.81 | P14: ='Cost Schedule '!P10 -> 18444.894
B15: Purchase of stock in trade | C15: 1103.63 | D15: 973.74 | E15: 1160.89 | F15: 1361.59 | G15: 1337.13 | H15: 941.48 | I15: 809.35 | J15: ='Cost Schedule '!J11 -> 1495.8295 | K15: ='Cost Schedule '!K11 -> 1673.1972 | L15: ='Cost Schedule '!L11 -> 1737.5779 | M15: ='Cost Schedule '!M11 -> 1982.8026 | N15: ='Cost Schedule '!N11 -> 2318.432 | O15: ='Cost Schedule '!O11 -> 2563.7996 | P15: ='Cost Schedule '!P11 -> 2817.8731
B16: Changes in inventories of finished goods, work in progress and stock in trade | C16: -55.18 | D16: 52.57 | E16: -37.12 | F16: -75.26 | G16: -72.53 | H16: 3.66 | I16: -64.75 | J16: ='Cost Schedule '!J12 -> -44.268038 | K16: ='Cost Schedule '!K12 -> -49.517113 | L16: ='Cost Schedule '!L12 -> -51.422415 | M16: ='Cost Schedule '!M12 -> -58.67967 | N16: ='Cost Schedule '!N12 -> -68.612388 | O16: ='Cost Schedule '!O12 -> -75.873873 | P16: ='Cost Schedule '!P12 -> -83.393003
A17: V | B17: Cost of goods sold | C17: =SUM(C14:C16) -> 6561.46 | D17: =SUM(D14:D16) -> 6927.47 | E17: =SUM(E14:E16) -> 7626.1 | F17: =SUM(F14:F16) -> 8760.3 | G17: =SUM(G14:G16) -> 9591.3 | H17: =SUM(H14:H16) -> 9492.03 | I17: =SUM(I14:I16) -> 10604.05 | J17: =SUM(J14:J16) -> 11242.782 | ... P17: =SUM(P14:P16) -> 21179.374
B18: Employee benefits expense | C18: 441.82 | D18: 486.69 | E18: 527.38 | F18: 542.26 | G18: 658.38 | H18: 708.7 | I18: 704.59 | J18: ='Cost Schedule '!J24 -> 774.30342 | K18: ='Cost Schedule '!K24 -> 839.86184 | L18: ='Cost Schedule '!L24 -> 918.08185 | M18: ='Cost Schedule '!M24 -> 1012.1373 | N18: ='Cost Schedule '!N24 -> 1126.1977 | O18: ='Cost Schedule '!O24 -> 1265.8032 | P18: ='Cost Schedule '!P24 -> 1438.4057
B19: Finance cost | C19: 9.09 | D19: 76.9 | E19: 110.9 | F19: 144.29 | G19: 169.1 | H19: 164 | I19: 138.8 | J19: ='Debt Schedule'!J30 -> 124.53595 | K19: ='Debt Schedule'!K30 -> 187.7497 | L19: ='Debt Schedule'!L30 -> 279.95303 | M19: ='Debt Schedule'!M30 -> 420.59917 | N19: ='Debt Schedule'!N30 -> 642.57453 | O19: ='Debt Schedule'!O30 -> 1001.5613 | P19: ='Debt Schedule'!P30 -> 1591.9432
B20: Depreciation and amortisation expense | C20: 161.88 | D20: 184.81 | E20: 197.85 | F20: 200.54 | G20: 225.91 | H20: 300.46 | I20: 313.34 | J20: ='Asset Schedule'!J27 -> -281.33107 | K20: ='Asset Schedule'!K27 -> -273.68575 | L20: ='Asset Schedule'!L27 -> -271.10684 | M20: ='Asset Schedule'!M27 -> -274.63999 | N20: ='Asset Schedule'!N27 -> -285.11669 | O20: ='Asset Schedule'!O27 -> -302.69535 | P20: ='Asset Schedule'!P27 -> -328.79864
B21: Other expenses | C21: 2317.97 | D21: 2342.21 | E21: 2473.37 | F21: 2632.19 | G21: 3219.96 | H21: 3398.7 | I21: 3446.88 | J21: ='Cost Schedule '!J28 -> 3760.9658 | K21: ='Cost Schedule '!K28 -> 4079.3978 | L21: ='Cost Schedule '!L28 -> 4459.3299 | M21: ='Cost Schedule '!M28 -> 4916.1785 | N21: ='Cost Schedule '!N28 -> 5470.1954 | O21: ='Cost Schedule '!O28 -> 6148.2909 | P21: ='Cost Schedule '!P28 -> 6986.6598
A22: VI | B22: Total expenses | C22: =SUM(C17:C21) -> 9492.22 | D22: =SUM(D17:D21) -> 10018.08 | E22: =SUM(E17:E21) -> 10935.6 | F22: =SUM(F17:F21) -> 12279.58 | G22: =SUM(G17:G21) -> 13864.65 | H22: =SUM(H17:H21) -> 14063.89 | I22: =SUM(I17:I21) -> 15207.66 | J22: =SUM(J17:J21) -> 15621.256 | ... P22: =SUM(P17:P21) -> 30867.584
A23: VII | B23: Profit before share of profits/(loss) of associates (III-VI) | C23: =C12-C22 -> 1768.9 | D23: =D12-D22 -> 1860.87 | E23: =E12-E22 -> 2513.41 | F23: =F12-F22 -> 2079.51 | G23: =G12-G22 -> 2651.76 | H23: =H12-H22 -> 2919.56 | I23: =I12-I22 -> 2962.1 | J23: =J12-J22 -> 3919.8453 | ... P23: =P12-P22 -> 11536.372
B24: Share of profits/(loss) of associates | C24: -0.97 | D24: 0.44 | E24: 0.81 | F24: -0.2 | G24: 5.41 | H24: -3.19 | I24: -10.74
A25: VIII | B25: Profit before exceptional items and tax | C25: =SUM(C23:C24) -> 1767.93 | D25: =SUM(D23:D24) -> 1861.31 | E25: =SUM(E23:E24) -> 2514.22 | F25: =SUM(F23:F24) -> 2079.31 | G25: =SUM(G23:G24) -> 2657.17 | H25: =SUM(H23:H24) -> 2916.37 | I25: =SUM(I23:I24) -> 2951.36 | J25: =SUM(J23:J24) -> 3919.8453 | ... P25: =SUM(P23:P24) -> 11536.372
A26: IX | B26: Exceptional Items | C26: 0 | D26: 17.01 | E26: 0.61 | F26: 0.98 | G26: -375.6 | H26: 2.9 | I26: 24.79
A27: X | B27: Profit before tax (VIII-IX) | C27: =C25-C26 -> 1767.93 | D27: =D25-D26 -> 1844.3 | E27: =E25-E26 -> 2513.61 | F27: =F25-F26 -> 2078.33 | G27: =G25-G26 -> 3032.77 | H27: =H25-H26 -> 2913.47 | I27: =I25-I26 -> 2926.57 | J27: =J25-J26 -> 3919.8453 | ... P27: =P25-P26 -> 11536.372
A28: XI | B28: Tax Expense :
B29: (i) Current Tax | C29: 599.78 | D29: 447.69 | E29: 657.12 | F29: 612.24 | G29: 720.97 | H29: 765.69 | I29: 741.68 | J29: ='Cost Schedule '!J36 -> 1026.6887 | K29: ='Cost Schedule '!K36 -> 1080.1799 | L29: ='Cost Schedule '!L36 -> 1454.8228 | M29: ='Cost Schedule '!M36 -> 1605.1271 | N29: ='Cost Schedule '!N36 -> 1719.869 | O29: ='Cost Schedule '!O36 -> 2219.6396 | P29: ='Cost Schedule '!P36 -> 3021.6148
B30: (ii) Deffered Tax | C30: 12.69 | D30: 3.01 | E30: 5.9 | F30: -49.89 | G30: -4.52 | H30: 13.56 | I30: 7.03 | J30: ='Cost Schedule '!J37 -> -17.220281 | K30: ='Cost Schedule '!K37 -> -18.117469 | L30: ='Cost Schedule '!L37 -> -24.401219 | M30: ='Cost Schedule '!M37 -> -26.92222 | N30: ='Cost Schedule '!N37 -> -28.846745 | O30: ='Cost Schedule '!O37 -> -37.229217 | P30: ='Cost Schedule '!P37 -> -50.680459
B31: Total tax expense | C31: =SUM(C29:C30) -> 612.47 | D31: =SUM(D29:D30) -> 450.7 | E31: =SUM(E29:E30) -> 663.02 | F31: =SUM(F29:F30) -> 562.35 | G31: =SUM(G29:G30) -> 716.45 | H31: =SUM(H29:H30) -> 779.25 | I31: =SUM(I29:I30) -> 748.71 | J31: =SUM(J29:J30) -> 1009.4684 | ... P31: =SUM(P29:P30) -> 2970.9343
A32: XII | B32: Profit for the year (X-XI) | C32: =C27-C31 -> 1155.46 | D32: =D27-D31 -> 1393.6 | E32: =E27-E31 -> 1850.59 | F32: =F27-F31 -> 1515.98 | G32: =G27-G31 -> 2316.32 | H32: =H27-H31 -> 2134.22 | I32: =I27-I31 -> 2177.86 | J32: =J27-J31 -> 2910.3768 | ... P32: =P27-P31 -> 8565.4372
A33: XIII | B33: Other comprehensive income :
B34: Remeasurements of the net defined benefit (liability)/asset | C34: -4.09 | D34: -6.5 | E34: 3.5 | F34: 0.17 | G34: -0.16 | H34: -2.39 | I34: -1.92
B35: Income-tax relating to items not to be reclassified subsequently to statement of profit or loss | C35: 1.43 | D35: 1.57 | E35: -0.92 | F35: -0.05 | G35: 0.04 | H35: 0.64 | I35: 0.5
B36: Foreign currency translation reserve | C36: 6.5 | D36: 10.05 | E36: -4.08 | F36: 6.17 | G36: 15.43 | H36: 2.87 | I36: 7.68
B37: Other comprehensive income/(loss),net of tax | C37: =SUM(C34:C36) -> 3.84 | D37: =SUM(D34:D36) -> 5.12 | E37: =SUM(E34:E36) -> -1.5 | F37: =SUM(F34:F36) -> 6.29 | G37: =SUM(G34:G36) -> 15.31 | H37: =SUM(H34:H36) -> 1.12 | I37: =SUM(I34:I36) -> 6.26
A38: XIV | B38: Total comprehensive income for the year ( XII+XIII) | C38: =SUM(C32+C37) -> 1159.3 | D38: =SUM(D32+D37) -> 1398.72 | E38: =SUM(E32+E37) -> 1849.09 | F38: =SUM(F32+F37) -> 1522.27 | G38: =SUM(G32+G37) -> 2331.63 | H38: =SUM(H32+H37) -> 2135.34 | I38: =SUM(I32+I37) -> 2184.12 | J38: =SUM(J32+J37) -> 2910.3768 | ... P38: =SUM(P32+P37) -> 8565.4372
B39: Profit attributable to :
B40: Owners of the company | C40: 1159.12 | D40: 1402.63 | E40: 1863.9 | F40: 1524.82 | G40: 2321.77 | H40: 2139.81 | I40: 2178.73
B41: Non-controlling interests | C41: -3.66 | D41: -9.03 | E41: -13.31 | F41: -8.84 | G41: -5.45 | H41: -5.59 | I41: -0.87
...

Sheet CFS
B1: Britannia Industries Limited
B2: CASH FLOW STATEMENT
B4: Particulars | C4: 2019 | D4: 2020 | E4: 2021 | F4: 2022 | G4: 2023 | H4: 2024 | I4: 2025 | J4: 2026 | K4: 2027 | L4: 2028 | M4: 2029 | N4: 2030 | O4: 2031 | P4: 2032
C5: Actual | D5: Actual | E5: Actual | F5: Actual | G5: Actual | H5: Actual | I5: Actual | J5: Forecast | K5: Forecast | L5: Forecast | M5: Forecast | N5: Forecast | O5: Forecast | P5: Forecast
A6: I | B6: Cash flow from operating activities
B7: Profit before tax and share of profits / (loss) of associates and after exceptional item | C7: ='Income Statement'!C23 -> 1768.9 | D7: ='Income Statement'!D27 -> 1844.3 | E7: ='Income Statement'!E27 -> 2513.61 | F7: 2078.53 | G7: 3027.36 | H7: 2916.66 | I7: 2937.31 | J7: ='Income Statement'!J27 -> 3919.8453 | K7: ='Income Statement'!K27 -> 4124.0719 | L7: ='Income Statement'!L27 -> 5554.4393 | M7: ='Income Statement'!M27 -> 6128.2936 | N7: ='Income Statement'!N27 -> 6566.3725 | O7: ='Income Statement'!O27 -> 8474.471 | P7: ='Income Statement'!P27 -> 11536.372
B8: Adjustments for
B9: Depreciation and amortisation expense | C9: 161.88 | D9: 184.81 | E9: 197.85 | F9: 200.54 | G9: 225.91 | H9: 300.46 | I9: 313.34 | J9: =-'Asset Schedule'!J10 -> 281.33107 | K9: =-'Asset Schedule'!K10 -> 273.68575 | L9: =-'Asset Schedule'!L10 -> 271.10684 | M9: =-'Asset Schedule'!M10 -> 274.63999 | N9: =-'Asset Schedule'!N10 -> 285.11669 | O9: =-'Asset Schedule'!O10 -> 302.69535 | P9: =-'Asset Schedule'!P10 -> 328.79864
B10: Share based payment expense | C10: 16.12 | D10: 21.58 | E10: 18.94 | F10: 4.78 | G10: 0 | H10: 0 | I10: 0
B11: Net gain on financial asset measured at fair value through Statement of Profit and Loss | C11: -63.85 | D11: -89.88 | E11: -65.47 | F11: -28.91 | G11: -42.08 | H11: -25.17 | I11: -81.35
B12: Profit on sale of property, plant and equipment | C12: -0.97 | D12: -0.11 | E12: -0.33 | F12: -0.95 | G12: -0.83 | H12: -0.45 | I12: -1.24
B13: Exceptional items-Gain on sale of investments (including fair valuation gain) | C13: 0 | D13: 0 | E13: 0 | F13: 0 | G13: -375.6 | H13: 0 | I13: 0
B14: Interest income from financial assets carried at amortised cost | C14: -136.77 | D14: -176.77 | E14: -234.66 | F14: -184.6 | G14: -163.15 | H14: -178.75 | I14: -132.8 | J14: =-('Other Schedule'!J18) -> -209.832 | K14: =-('Other Schedule'!K18) -> -573.46561 | L14: =-('Other Schedule'!L18) -> -1088.5837 | M14: =-('Other Schedule'!M18) -> -1846.3108 | N14: =-('Other Schedule'!N18) -> -2840.0584 | O14: =-('Other Schedule'!O18) -> -4267.4366 | P14: =-('Other Schedule'!P18) -> -6506.7073
B15: Bad debts | C15: 0 | D15: 0 | E15: 0 | F15: 0 | G15: 5.59 | H15: 0 | I15: 0
B16: Finance costs | C16: 9.09 | D16: 76.9 | E16: 110.9 | F16: 144.29 | G16: 169.1 | H16: 164 | I16: 138.8 | J16: ='Debt Schedule'!J30 -> 124.53595 | K16: ='Debt Schedule'!K30 -> 187.7497 | L16: ='Debt Schedule'!L30 -> 279.95303 | M16: ='Debt Schedule'!M30 -> 420.59917 | N16: ='Debt Schedule'!N30 -> 642.57453 | O16: ='Debt Schedule'!O30 -> 1001.5613 | P16: ='Debt Schedule'!P30 -> 1591.9432
B17: Changes in working capital
B18: Inventories | C18: -127.21 | D18: 42.99 | E18: -351.44 | F18: -274.76 | G18: 177.15 | H18: 12.6 | I18: -54.33 | J18: =-('Balance Sheet'!J24-'Balance Sheet'!I24) -> -291.16933 | K18: =-('Balance Sheet'!K24-'Balance Sheet'!J24) -> -99.057526 | L18: =-('Balance Sheet'!L24-'Balance Sheet'!K24) -> -46.450389 | M18: =-('Balance Sheet'!M24-'Balance Sheet'!L24) -> -357.64923 | N18: =-('Balance Sheet'!N24-'Balance Sheet'!M24) -> -220.03558 | O18: =-('Balance Sheet'!O24-'Balance Sheet'!N24) -> -219.14565 | P18: =-('Balance Sheet'!P24-'Balance Sheet'!O24) -> -313.94554
B19: Trade receivables | C19: -86.67 | D19: 78.85 | E19: 61.4 | F19: -72.21 | G19: 1.29 | H19: -63.65 | I19: -53.44 | J19: =-('Balance Sheet'!J27-'Balance Sheet'!I27) -> 19.930892 | K19: =-('Balance Sheet'!K27-'Balance Sheet'!J27) -> -94.208863 | L19: =-('Balance Sheet'!L27-'Balance Sheet'!K27) -> 5.5852626 | M19: =-('Balance Sheet'!M27-'Balance Sheet'!L27) -> -112.15052 | N19: =-('Balance Sheet'!N27-'Balance Sheet'!M27) -> -17.080377 | O19: =-('Balance Sheet'!O27-'Balance Sheet'!N27) -> -141.09331 | P19: =-('Balance Sheet'!P27-'Balance Sheet'!O27) -> -54.465998
B20: Loans receivable, other financial assets, other bank balances and other assets | C20: 10.9 | D20: -23.66 | E20: -170.82 | F20: -44.29 | G20: -64.82 | H20: -24.52 | I20: -106.58
B21: Accounts payables, other financial liabilities, other liabilities and provisions | C21: 200.49 | D21: 29.21 | E21: 404.71 | F21: 64.01 | G21: 292.04 | H21: 236.67 | I21: 210.15 | J21: ='Working Capital Schedule'!J37-'Working Capital Schedule'!I37 -> 113.22976 | K21: ='Working Capital Schedule'!K37-'Working Capital Schedule'!J37 -> 315.73716 | L21: ='Working Capital Schedule'!L37-'Working Capital Schedule'!K37 -> -160.03132 | M21: ='Working Capital Schedule'!M37-'Working Capital Schedule'!L37 -> 753.11153 | N21: ='Working Capital Schedule'!N37-'Working Capital Schedule'!M37 -> 58.613916 | O21: ='Working Capital Schedule'!O37-'Working Capital Schedule'!N37 -> 534.81192 | P21: ='Working Capital Schedule'!P37-'Working Capital Schedule'!O37 -> 79.669368
B22: Cash generated from operating activities | C22: =SUM(C7:C21) -> 1751.91 | D22: =SUM(D7:D21) -> 1988.22 | E22: =SUM(E7:E21) -> 2484.69 | F22: =SUM(F7:F21) -> 1886.43 | G22: =SUM(G7:G21) -> 3251.96 | H22: =SUM(H7:H21) -> 3337.85 | I22: =SUM(I7:I21) -> 3169.86 | J22: =SUM(J7:J21) -> 3957.8716 | ... P22: =SUM(P7:P21) -> 6661.6638
B23: Income-tax paid, net of refund | C23: -596.13 | D23: -503.25 | E23: -632.81 | F23: -586.91 | G23: -725.75 | H23: -764.87 | I23: -689.21 | J23: =-('Cost Schedule '!J38) -> -1009.4684 | K23: =-('Cost Schedule '!K38) -> -1062.0624 | L23: =-('Cost Schedule '!L38) -> -1430.4215 | M23: =-('Cost Schedule '!M38) -> -1578.2049 | N23: =-('Cost Schedule '!N38) -> -1691.0223 | O23: =-('Cost Schedule '!O38) -> -2182.4104 | P23: =-('Cost Schedule '!P38) -> -2970.9343
B25: Net cash generated from operating activities | C25: =SUM(C22:C23) -> 1155.78 | D25: =SUM(D22:D23) -> 1484.97 | E25: =SUM(E22:E23) -> 1851.88 | F25: =SUM(F22:F23) -> 1299.52 | G25: =SUM(G22:G23) -> 2526.21 | H25: =SUM(H22:H23) -> 2572.98 | I25: =SUM(I22:I23) -> 2480.65 | J25: =SUM(J22:J23) -> 2948.4032 | ... P25: =SUM(P22:P23) -> 3690.7295
A27: II | B27: Cash flow from investing activities
B28: Acquisition of property, plant and equipment and other intangible assets | C28: -401.21 | D28: -244.17 | E28: -242.07 | F28: -550.18 | G28: -711.46 | H28: -552.87 | I28: -374.85 | J28: =-('Asset Schedule'!J8) -> -195.42542 | K28: =-('Asset Schedule'!K8) -> -229.78572 | L28: =-('Asset Schedule'!L8) -> -275.87598 | M28: =-('Asset Schedule'!M8) -> -338.8667 | N28: =-('Asset Schedule'!N8) -> -417.5453 | O28: =-('Asset Schedule'!O8) -> -505.54575 | P28: =-('Asset Schedule'!P8) -> -616.84705
B29: Proceeds from sale of non-current investments | C29: 0 | D29: 0 | E29: 0 | F29: 191.78 | G29: 443.27 | H29: 294.22 | I29: 572.16
B30: Proceeds from sale of property, plant and equipment | C30: 1.82 | D30: 0.73 | E30: 2.17 | F30: 3.16 | G30: 78.43 | H30: 64.52 | I30: 4.58 | J30: =-'Asset Schedule'!J22 -> 31.493445 | K30: =-'Asset Schedule'!K22 -> 30.200782 | L30: =-'Asset Schedule'!L22 -> 29.384869 | M30: =-'Asset Schedule'!M22 -> 29.113829 | N30: =-'Asset Schedule'!N22 -> 29.500452 | O30: =-'Asset Schedule'!O22 -> 30.633778 | P30: =-'Asset Schedule'!P22 -> 32.530029
B31: Purchase of investments, net | C31: -334.12 | D31: -1326.63 | E31: 0 | F31: -20.68 | G31: -400.82 | H31: -190.9 | I31: -945.05
B32: Sale of current investments, net | C32: 0 | D32: 0 | E32: 178.82 | F32: 876.87 | G32: -1067.32 | H32: 476.87 | I32: 347.31
B33: Investment in joint venture | C33: 0 | D33: 0 | E33: 0 | F33: 0 | G33: -214.91 | H33: 0 | I33: 0
B34: Proceeds from sale of equity shares in subsidiary (net of cash and cash equivalent) | C34: 0 | D34: 0 | E34: 0 | F34: 0 | G34: 261.8 | H34: 0 | I34: 0
B35: Inter-corporate deposits placed | C35: -874.3 | D35: -1293.41 | E35: =-1202.5 -> -1202.5 | F35: -740 | G35: -850 | H35: -610 | I35: -75
B36: Inter-corporate deposits redeemed | C36: 635.4 | D36: 1204.2 | E36: 1491.41 | F36: 941.5 | G36: 938 | H36: 860 | I36: 460
B37: Changes in other bank balances | C37: 0 | D37: 0 | E37: 0 | F37: 1.69 | G37: -28.69 | H37: -27.95 | I37: -56.15
B38: Consideration paid under business combination | C38: 0 | D38: 0 | E38: 0 | F38: 0 | G38: -1.45 | H38: 0 | I38: 0
B39: Derecognition of net asset on loss of control [refer note 58(b)] | C39: 0 | D39: 0 | E39: 0 | F39: 0 | G39: -138.59 | H39: 0 | I39: 0
B40: Interest received | C40: 116.88 | D40: 127.62 | E40: 233.43 | F40: 206.75 | G40: 174.68 | H40: 170.26 | I40: 151.36 | J40: ='Other Schedule'!J13 -> 217.3739 | K40: ='Other Schedule'!K13 -> 573.46707 | L40: ='Other Schedule'!L13 -> 1088.58 | M40: ='Other Schedule'!M13 -> 1846.3069 | N40: ='Other Schedule'!N13 -> 2840.0587 | O40: ='Other Schedule'!O13 -> 4267.4362 | P40: ='Other Schedule'!P13 -> 6506.7114
B41: Net cash used in investing activities | C41: =SUM(C28:C40) -> -855.53 | D41: =SUM(D28:D40) -> -1531.66 | E41: =SUM(E28:E40) -> 461.26 | F41: =SUM(F28:F40) -> 910.89 | G41: =SUM(G28:G40) -> -1517.06 | H41: =SUM(H28:H40) -> 484.15 | I41: =SUM(I28:I40) -> 84.36 | J41: =SUM(J28:J40) -> 53.441927 | ... P41: =SUM(P28:P40) -> 5922.3944
A43: III | B43: Cash flow from financing activities
B44: Proceeds from share allotment | C44: 29.79 | D44: 23.97 | E44: 103.15 | F44: 0 | G44: 0 | H44: 0 | I44: 0
...

Sheet RATIO ANALYSIS
B1: Britannia Industries Limited
B2: RATIO ANALYSIS
B4: Particulars | C4: 2019 | D4: 2020 | E4: 2021 | F4: 2022 | G4: 2023 | H4: 2024 | I4: 2025 | J4: 2026 | K4: 2027 | L4: 2028 | M4: 2029 | N4: 2030 | O4: 2031 | P4: 2032 | R4: TRENDS | S4: MEDIAN
C5: Actual | D5: Actual | E5: Actual | F5: Actual | G5: Actual | H5: Actual | I5: Actual | J5: Forecast | K5: Forecast | L5: Forecast | M5: Forecast | N5: Forecast | O5: Forecast | P5: Forecast
B6: GROWTH FACTORS | E6: 2021 | F6: 2022 | G6: 2023 | H6: 2024 | I6: 2025
B7: Revenue Growth (%) | C7: ='Income Statement'!C7 -> 0 | D7: ='Income Statement'!D7 -> 0.04287891 | E7: ='Income Statement'!E7 -> 0.12574723 | F7: ='Income Statement'!F7 -> 0.08240524 | G7: ='Income Statement'!G7 -> 0.14630895 | H7: ='Income Statement'!H7 -> 0.035115015 | I7: ='Income Statement'!I7 -> 0.059760513 | J7: ='Income Statement'!J7 -> 0.086167566 | ... P7: ='Income Statement'!P7 -> 0.13635812 | S7: =MEDIAN(C7:P7) -> 0.089650943
B8: Gross Profit Growth (%) | D8: 0.039808956 | E8: 0.17935481 | F8: -0.024333762 | G8: 0.24800966 | H8: 0.084657749 | I8: 0.0084345164 | J8: 0.10115328 | K8: 0.0374935 | L8: 0.17511945 | M8: 0.051171165 | N8: 0.031276057 | O8: 0.15353979 | P8: 0.1946328 | S8: =MEDIAN(C8:P8) -> 0.084657749
B9: EBITDA Growth (%) | D9: 0.086188045 | E9: 0.34014558 | F9: -0.14144191 | G9: 0.41459086 | H9: -0.01454294 | I9: 0.00023091065 | J9: 0.11375352 | K9: 0.073101789 | L9: 0.37768657 | M9: 0.12779629 | N9: 0.10353067 | O9: 0.32489339 | P9: 0.39529553 | S9: =MEDIAN(C9:P9) -> 0.11375352
B10: EBIT Growth (%) | D10: 0.090708039 | E10: 0.35440432 | F10: -0.15295301 | G10: 0.27103346 | H10: 0.089906485 | I10: 0.0031781896 | J10: 0.30879346 | K10: 0.066126401 | L10: 0.35311543 | M10: 0.12246355 | N10: 0.10078868 | O10: 0.31448218 | P10: 0.38542316 | S10: =MEDIAN(C10:P10) -> 0.12246355
B11: Pre-Tax Growth (%) | D11: ='Income Statement'!D25/'Income Statement'!C25-1 -> 0.052818833 | E11: ='Income Statement'!E25/'Income Statement'!D25-1 -> 0.35077983 | F11: ='Income Statement'!F25/'Income Statement'!E25-1 -> -0.17298009 | G11: ='Income Statement'!G25/'Income Statement'!F25-1 -> 0.2779095 | H11: ='Income Statement'!H25/'Income Statement'!G25-1 -> 0.097547391 | I11: ='Income Statement'!I25/'Income Statement'!H25-1 -> 0.011997792 | J11: ='Income Statement'!J25/'Income Statement'!I25-1 -> 0.32814881 | K11: ='Income Statement'!K25/'Income Statement'!J25-1 -> 0.052100685 | ... P11: ='Income Statement'!P25/'Income Statement'!O25-1 -> 0.36130875 | S11: =MEDIAN(C11:P11) -> 0.10331452
B14: MARGIN
B15: Gross Profit Margin (%) | C15: =('Income Statement'!C10-'Income Statement'!C17)/'Income Statement'!C10 -> 0.40645356 | D15: =('Income Statement'!D10-'Income Statement'!D17)/'Income Statement'!D10 -> 0.40278114 | E15: =('Income Statement'!E10-'Income Statement'!E17)/'Income Statement'!E10 -> 0.41945655 | F15: =('Income Statement'!F10-'Income Statement'!F17)/'Income Statement'!F10 -> 0.38029578 | G15: =('Income Statement'!G10-'Income Statement'!G17)/'Income Statement'!G10 -> 0.41159654 | H15: =('Income Statement'!H10-'Income Statement'!H17)/'Income Statement'!H10 -> 0.43396284 | I15: =('Income Statement'!I10-'Income Statement'!I17)/'Income Statement'!I10 -> 0.40900379 | J15: =('Income Statement'!J10-'Income Statement'!J17)/'Income Statement'!J10 -> 0.41818772 | ... P15: =('Income Statement'!P10-'Income Statement'!P17)/'Income Statement'!P10 -> 0.41 | S15: =MEDIAN(C15:P15) -> 0.40950189
B16: EBITDA Margin (%) | C16: =('Income Statement'!C27+'Income Statement'!C19+'Income Statement'!C20)/'Income Statement'!C10 -> 0.17539194 | D16: =('Income Statement'!D27+'Income Statement'!D19+'Income Statement'!D20)/'Income Statement'!D10 -> 0.18155963 | E16: =('Income Statement'!E27+'Income Statement'!E19+'Income Statement'!E20)/'Income Statement'!E10 -> 0.21485459 | F16: =('Income Statement'!F27+'Income Statement'!F19+'Income Statement'!F20)/'Income Statement'!F10 -> 0.1714145 | G16: =('Income Statement'!G27+'Income Statement'!G19+'Income Statement'!G20)/'Income Statement'!G10 -> 0.21028616 | H16: =('Income Statement'!H27+'Income Statement'!H19+'Income Statement'!H20)/'Income Statement'!H10 -> 0.20143572 | I16: =('Income Statement'!I27+'Income Statement'!I19+'Income Statement'!I20)/'Income Statement'!I10 -> 0.18830587 | J16: =('Income Statement'!J27+'Income Statement'!J19+'Income Statement'!J20)/'Income Statement'!J10 -> 0.19473728 | ... P16: =('Income Statement'!P27+'Income Statement'!P19+'Income Statement'!P20)/'Income Statement'!P10 -> 0.35655985 | S16: =MEDIAN(C16:P16) -> 0.20586094
B17: EBIT Margin (%) | C17: =('Income Statement'!C25+'Income Statement'!C19)/'Income Statement'!C10 -> 0.16074835 | D17: =('Income Statement'!D25+'Income Statement'!D19)/'Income Statement'!D10 -> 0.16709355 | E17: =('Income Statement'!E25+'Income Statement'!E19)/'Income Statement'!E10 -> 0.19983953 | F17: =('Income Statement'!F25+'Income Statement'!F19)/'Income Statement'!F10 -> 0.15729762 | G17: =('Income Statement'!G25+'Income Statement'!G19)/'Income Statement'!G10 -> 0.17338495 | H17: =('Income Statement'!H25+'Income Statement'!H19)/'Income Statement'!H10 -> 0.18369136 | I17: =('Income Statement'!I25+'Income Statement'!I19)/'Income Statement'!I10 -> 0.17222409 | J17: =('Income Statement'!J25+'Income Statement'!J19)/'Income Statement'!J10 -> 0.20929612 | ... P17: =('Income Statement'!P25+'Income Statement'!P19)/'Income Statement'!P10 -> 0.36571929 | S17: =MEDIAN(C17:P17) -> 0.20277898
B18: Pre-Tax Margin (%) | C18: ='Income Statement'!C25/'Income Statement'!C10 -> 0.15992608 | D18: ='Income Statement'!D25/'Income Statement'!D10 -> 0.16046398 | E18: ='Income Statement'!E25/'Income Statement'!E10 -> 0.19139717 | F18: ='Income Statement'!F25/'Income Statement'!F10 -> 0.14709053 | G18: ='Income Statement'!G25/'Income Statement'!G10 -> 0.16301106 | H18: ='Income Statement'!H25/'Income Statement'!H10 -> 0.17391157 | I18: ='Income Statement'!I25/'Income Statement'!I10 -> 0.16448834 | J18: ='Income Statement'!J25/'Income Statement'!J10 -> 0.20285141 | ... P18: ='Income Statement'!P25/'Income Statement'!P10 -> 0.32137207 | S18: =MEDIAN(C18:P18) -> 0.194079
B19: Effective Tax Rate (%) | C19: ='Income Statement'!C31/'Income Statement'!C27 -> 0.3464334 | D19: ='Income Statement'!D31/'Income Statement'!D27 -> 0.24437456 | E19: ='Income Statement'!E31/'Income Statement'!E27 -> 0.26377203 | F19: ='Income Statement'!F31/'Income Statement'!F27 -> 0.27057782 | G19: ='Income Statement'!G31/'Income Statement'!G27 -> 0.23623618 | H19: ='Income Statement'!H31/'Income Statement'!H27 -> 0.26746457 | I19: ='Income Statement'!I31/'Income Statement'!I27 -> 0.25583191 | J19: ='Income Statement'!J31/'Income Statement'!J27 -> 0.25752762 | ... P19: ='Income Statement'!P31/'Income Statement'!P27 -> 0.25752762 | S19: =MEDIAN(C19:P19) -> 0.25752762
B21: LIQUIDITY RATIOS
B22: Current Ratio | C22: ='Balance Sheet'!C34/'Balance Sheet'!C67 -> 1.9046781 | D22: ='Balance Sheet'!D34/'Balance Sheet'!D67 -> 1.4252577 | E22: ='Balance Sheet'!E34/'Balance Sheet'!E67 -> 1.2228417 | F22: ='Balance Sheet'!F34/'Balance Sheet'!F67 -> 0.96025213 | G22: ='Balance Sheet'!G34/'Balance Sheet'!G67 -> 1.1479852 | H22: ='Balance Sheet'!H34/'Balance Sheet'!H67 -> 1.1871139 | I22: ='Balance Sheet'!I34/'Balance Sheet'!I67 -> 1.081647 | J22: ='Balance Sheet'!J34/'Balance Sheet'!J67 -> 1.4353612 | ... P22: ='Balance Sheet'!P34/'Balance Sheet'!P67 -> 1.9362629 | S22: =MEDIAN(C22:P22) -> 1.5560963
B23: Quick Ratio | C23: =('Balance Sheet'!C34-'Balance Sheet'!C24)/'Balance Sheet'!C67 -> 1.4826322 | D23: =('Balance Sheet'!D34-'Balance Sheet'!D24)/'Balance Sheet'!D67 -> 1.1378924 | E23: =('Balance Sheet'!E34-'Balance Sheet'!E24)/'Balance Sheet'!E67 -> 0.92084709 | F23: =('Balance Sheet'!F34-'Balance Sheet'!F24)/'Balance Sheet'!F67 -> 0.63050922 | G23: =('Balance Sheet'!G34-'Balance Sheet'!G24)/'Balance Sheet'!G67 -> 0.85936774 | H23: =('Balance Sheet'!H34-'Balance Sheet'!H24)/'Balance Sheet'!H67 -> 0.89791182 | I23: =('Balance Sheet'!I34-'Balance Sheet'!I24)/'Balance Sheet'!I67 -> 0.73990537 | J23: =('Balance Sheet'!J34-'Balance Sheet'!J24)/'Balance Sheet'!J67 -> 1.0618246 | ... P23: =('Balance Sheet'!P34-'Balance Sheet'!P24)/'Balance Sheet'!P67 -> 1.8283738 | S23: =MEDIAN(C23:P23) -> 1.2451614
B25: TURNOVER RATIO
B26: Receivable Turnover Ratio | C26: ='Working Capital Schedule'!C30 -> 0 | D26: ='Working Capital Schedule'!D30 -> 32.464456 | E26: ='Working Capital Schedule'!E30 -> 45.482887 | F26: ='Working Capital Schedule'!F30 -> 47.984589 | G26: ='Working Capital Schedule'!G30 -> 49.330579 | H26: ='Working Capital Schedule'!H30 -> 46.434907 | I26: ='Working Capital Schedule'!I30 -> 42.622206 | J26: ='Working Capital Schedule'!J30 -> 44.053271 | ... P26: ='Working Capital Schedule'!P30 -> 44.053271 | S26: =MEDIAN(C26:P26) -> 44.053271
B27: Payable Turnover Ratio | C27: ='Working Capital Schedule'!C43 -> 0 | D27: ='Working Capital Schedule'!D43 -> 0.8902725 | E27: ='Working Capital Schedule'!E43 -> 0.98307611 | F27: ='Working Capital Schedule'!F43 -> 1.0324618 | G27: ='Working Capital Schedule'!G43 -> 0.96487253 | H27: ='Working Capital Schedule'!H43 -> 0.61208794 | I27: ='Working Capital Schedule'!I43 -> 0.47894642 | J27: ='Working Capital Schedule'!J43 -> 0.82695289 | ... P27: ='Working Capital Schedule'!P43 -> 0.82695289 | S27: =MEDIAN(C27:P27) -> 0.82695289
B28: Inventory Turnover Ratio | C28: ='Working Capital Schedule'!C17 -> 0 | D28: ='Working Capital Schedule'!D17 -> 9.1010812 | E28: ='Working Capital Schedule'!E17 -> 8.3233922 | F28: ='Working Capital Schedule'!F17 -> 7.1251495 | G28: ='Working Capital Schedule'!G17 -> 7.4910085 | H28: ='Working Capital Schedule'!H17 -> 7.9950389 | I28: ='Working Capital Schedule'!I17 -> 8.7719059 | J28: ='Working Capital Schedule'!J17 -> 8.134596 | ... P28: ='Working Capital Schedule'!P17 -> 8.0622195 | S28: =MEDIAN(C28:P28) -> 8.0545487
B29: Fixed Asset Turnover Ratio | C29: ='Income Statement'!C10/'Balance Sheet'!C44 -> 2.5792932 | D29: ='Income Statement'!D10/'Balance Sheet'!D44 -> 2.6134059 | E29: ='Income Statement'!E10/'Balance Sheet'!E44 -> 3.6652176 | F29: ='Income Statement'!F10/'Balance Sheet'!F44 -> 5.4673035 | G29: ='Income Statement'!G10/'Balance Sheet'!G44 -> 4.5730257 | H29: ='Income Statement'!H10/'Balance Sheet'!H44 -> 4.2282364 | I29: ='Income Statement'!I10/'Balance Sheet'!I44 -> 4.0952658 | J29: ='Income Statement'!J10/'Balance Sheet'!J44 -> 3.5419568 | ... P29: ='Income Statement'!P10/'Balance Sheet'!P44 -> 1.3855428 | S29: =MEDIAN(C29:P29) -> 2.8751665
B33: Receivable days | C33: ='Working Capital Schedule'!C32 -> 0 | D33: ='Working Capital Schedule'!D32 -> 11.243065 | E33: ='Working Capital Schedule'!E32 -> 8.0249963 | F33: ='Working Capital Schedule'!F32 -> 7.6066088 | G33: ='Working Capital Schedule'!G32 -> 7.3990617 | H33: ='Working Capital Schedule'!H32 -> 7.8604659 | I33: ='Working Capital Schedule'!I32 -> 8.5636112 | J33: ='Working Capital Schedule'!J32 -> 8.2854234 | ... P33: ='Working Capital Schedule'!P32 -> 8.2854234 | S33: =MEDIAN(C33:P33) -> 8.2854234
B34: Payable Days | C34: ='Working Capital Schedule'!C45 -> 0 | D34: ='Working Capital Schedule'!D45 -> 409.98683 | E34: ='Working Capital Schedule'!E45 -> 371.28356 | F34: ='Working Capital Schedule'!F45 -> 353.52397 | G34: ='Working Capital Schedule'!G45 -> 378.28831 | H34: ='Working Capital Schedule'!H45 -> 596.31954 | I34: ='Working Capital Schedule'!I45 -> 762.08942 | J34: ='Working Capital Schedule'!J45 -> 441.37944 | ... P34: ='Working Capital Schedule'!P45 -> 441.37944 | S34: =MEDIAN(C34:P34) -> 441.37944
B35: Inventory Days | C35: ='Working Capital Schedule'!C19 -> 0 | D35: ='Working Capital Schedule'!D19 -> 40.105125 | E35: ='Working Capital Schedule'!E19 -> 43.852313 | F35: ='Working Capital Schedule'!F19 -> 51.226996 | G35: ='Working Capital Schedule'!G19 -> 48.725082 | H35: ='Working Capital Schedule'!H19 -> 45.653311 | I35: ='Working Capital Schedule'!I19 -> 41.610114 | J35: ='Working Capital Schedule'!J19 -> 44.870083 | ... P35: ='Working Capital Schedule'!P19 -> 45.272893 | S35: =MEDIAN(C35:P35) -> 45.071488
B36: Cash Conversion Cycle | C36: =C35+C33-C34 -> 0 | D36: =D35+D33-D34 -> -358.63864 | E36: =E35+E33-E34 -> -319.40625 | F36: =F35+F33-F34 -> -294.69036 | G36: =G35+G33-G34 -> -322.16417 | H36: =H35+H33-H34 -> -542.80577 | I36: =I35+I33-I34 -> -711.9157 | J36: =J35+J33-J34 -> -388.22393 | ... P36: =P35+P33-P34 -> -387.82112 | S36: =MEDIAN(C36:P36) -> -387.52614
B39: CFO%Sales | C39: =CFS!C25/'Income Statement'!C10 -> 0.10455129 | D39: =CFS!D25/'Income Statement'!D10 -> 0.12801962 | E39: =CFS!E25/'Income Statement'!E10 -> 0.14097596 | F39: =CFS!F25/'Income Statement'!F10 -> 0.091928134 | G39: =CFS!G25/'Income Statement'!G10 -> 0.15497698 | H39: =CFS!H25/'Income Statement'!H10 -> 0.15343423 | I39: =CFS!I25/'Income Statement'!I10 -> 0.13825423 | J39: =CFS!J25/'Income Statement'!J10 -> 0.15257942 | ... P39: =CFS!P25/'Income Statement'!P10 -> 0.10281373 | S39: =MEDIAN(C39:P39) -> 0.1396151
B40: CFO%Totak Assets | D40: =CFS!D25/AVERAGE('Balance Sheet'!C36,'Balance Sheet'!D36) -> 0.21087258 | E40: =CFS!E25/AVERAGE('Balance Sheet'!D36,'Balance Sheet'!E36) -> 0.23366082 | F40: =CFS!F25/AVERAGE('Balance Sheet'!E36,'Balance Sheet'!F36) -> 0.16728941 | G40: =CFS!G25/AVERAGE('Balance Sheet'!F36,'Balance Sheet'!G36) -> 0.29931168 | H40: =CFS!H25/AVERAGE('Balance Sheet'!G36,'Balance Sheet'!H36) -> 0.27927286 | I40: =CFS!I25/AVERAGE('Balance Sheet'!H36,'Balance Sheet'!I36) -> 0.27698021 | J40: =CFS!J25/AVERAGE('Balance Sheet'!I36,'Balance Sheet'!J36) -> 0.30214746 | K40: =CFS!K25/AVERAGE('Balance Sheet'!J36,'Balance Sheet'!K36) -> 0.25797496 | ... P40: =CFS!P25/AVERAGE('Balance Sheet'!O36,'Balance Sheet'!P36) -> 0.078106196 | S40: =MEDIAN(C40:P40) -> 0.22733224
B41: CFO%Total Debt | D41: =CFS!D25/AVERAGE('Balance Sheet'!D54+'Balance Sheet'!D67,'Balance Sheet'!C54+'Balance Sheet'!C67) -> 0.5541305 | E41: =CFS!E25/AVERAGE('Balance Sheet'!E54+'Balance Sheet'!E67,'Balance Sheet'!D54+'Balance Sheet'!D67) -> 0.47311053 | F41: =CFS!F25/AVERAGE('Balance Sheet'!F54+'Balance Sheet'!F67,'Balance Sheet'!E54+'Balance Sheet'!E67) -> 0.27747985 | G41: =CFS!G25/AVERAGE('Balance Sheet'!G54+'Balance Sheet'!G67,'Balance Sheet'!F54+'Balance Sheet'!F67) -> 0.47086728 | H41: =CFS!H25/AVERAGE('Balance Sheet'!H54+'Balance Sheet'!H67,'Balance Sheet'!G54+'Balance Sheet'!G67) -> 0.47229014 | I41: =CFS!I25/AVERAGE('Balance Sheet'!I54+'Balance Sheet'!I67,'Balance Sheet'!H54+'Balance Sheet'!H67) -> 0.51870562 | J41: =CFS!J25/AVERAGE('Balance Sheet'!J54+'Balance Sheet'!J67,'Balance Sheet'!I54+'Balance Sheet'!I67) -> 0.60921618 | K41: =CFS!K25/AVERAGE('Balance Sheet'!K54+'Balance Sheet'!K67,'Balance Sheet'!J54+'Balance Sheet'!J67) -> 0.52599443 | ... P41: =CFS!P25/AVERAGE('Balance Sheet'!P54+'Balance Sheet'!P67,'Balance Sheet'!O54+'Balance Sheet'!O67) -> 0.14936793 | S41: =MEDIAN(C41:P41) -> 0.47229014
B44: Return on Capital employed | D44: =D52/D51 -> 0.40152763 | E44: =E52/E51 -> 0.5435999 | F44: =F52/F51 -> 0.57200332 | G44: =G52/G51 -> 0.65737987 | H44: =H52/H51 -> 0.6035521 | I44: =I52/I51 -> 0.60535348 | J44: =J52/J51 -> 0.68500718 | K44: =K52/K51 -> 0.58602854 | ... P44: =P52/P51 -> 0.50860051 | S44: =MEDIAN(C44:P44) -> 0.57200332
B45: Retained Earnings Percentage | C45: =('Income Statement'!C32--(CFS!C57))/'Income Statement'!C32 -> 0.69329964 | D45: =('Income Statement'!D32--(CFS!D57))/'Income Statement'!D32 -> 0.68963117 | E45: =('Income Statement'!E32--(CFS!E57))/'Income Statement'!E32 -> -0.52586472 | F45: =('Income Statement'!F32--(CFS!F57))/'Income Statement'!F32 -> -0.63912453 | G45: =('Income Statement'!G32--(CFS!G57))/'Income Statement'!G32 -> 0.41318989 | H45: =('Income Statement'!H32--(CFS!H57))/'Income Statement'!H32 -> 0.18824207 | I45: =('Income Statement'!I32--(CFS!I57))/'Income Statement'!I32 -> 0.18840513 | J45: =('Income Statement'!J32--(CFS!J57))/'Income Statement'!J32 -> 0.36914269 | ... P45: =('Income Statement'!P32--(CFS!P57))/'Income Statement'!P32 -> 0.78564638 | S45: =MEDIAN(C45:P45) -> 0.48399254
B46: Return on Equity | D46: ='Income Statement'!D32/AVERAGE('Balance Sheet'!D42,'Balance Sheet'!C42) -> 0.32199333 | E46: ='Income Statement'!E32/AVERAGE('Balance Sheet'!E42,'Balance Sheet'!D42) -> 0.46552854 | F46: ='Income Statement'!F32/AVERAGE('Balance Sheet'!F42,'Balance Sheet'!E42) -> 0.49657373 | G46: ='Income Statement'!G32/AVERAGE('Balance Sheet'!G42,'Balance Sheet'!F42) -> 0.7604003 | H46: ='Income Statement'!H32/AVERAGE('Balance Sheet'!H42,'Balance Sheet'!G42) -> 0.57096842 | I46: ='Income Statement'!I32/AVERAGE('Balance Sheet'!I42,'Balance Sheet'!H42) -> 0.52496011 | J46: ='Income Statement'!J32/AVERAGE('Balance Sheet'!J42,'Balance Sheet'!I42) -> 0.59481729 | K46: ='Income Statement'!K32/AVERAGE('Balance Sheet'!K42,'Balance Sheet'!J42) -> 0.50669911 | ... P46: ='Income Statement'!P32/AVERAGE('Balance Sheet'!P42,'Balance Sheet'!O42) -> 0.38037958 | S46: =MEDIAN(C46:P46) -> 0.49657373
B47: Interest Coverage Ratio | D47: =C52/'Income Statement'!C19 -> 195.49175 | E47: =D52/'Income Statement'!D19 -> 25.204291 | F47: =E52/'Income Statement'!E19 -> 23.671055 | G47: =F52/'Income Statement'!F19 -> 15.410631 | H47: =G52/'Income Statement'!G19 -> 16.713601 | I47: =H52/'Income Statement'!H19 -> 18.782744 | J47: =I52/'Income Statement'!I19 -> 22.263401 | K47: =J52/'Income Statement'!J19 -> 32.475612 | ... P47: =O52/'Income Statement'!O19 -> 9.4612602 | S47: =MEDIAN(C47:P47) -> 20.840612
B50: CAPITAL EMPLOYED | C50: ='Balance Sheet'!C36-'Balance Sheet'!C67 -> 4390.41 | D50: ='Balance Sheet'!D36-'Balance Sheet'!D67 -> 5263.77 | E50: ='Balance Sheet'!E36-'Balance Sheet'!E67 -> 4394.51 | F50: ='Balance Sheet'!F36-'Balance Sheet'!F67 -> 3380.27 | G50: ='Balance Sheet'!G36-'Balance Sheet'!G67 -> 5218.32 | H50: ='Balance Sheet'!H36-'Balance Sheet'!H67 -> 4989.15 | I50: ='Balance Sheet'!I36-'Balance Sheet'!I67 -> 5220.29 | J50: ='Balance Sheet'!J36-'Balance Sheet'!J67 -> 6587.9986 | ... P50: ='Balance Sheet'!P36-'Balance Sheet'!P67 -> 29433.8
B51: AVERAGE CAPITALL EMPLYOED | D51: =AVERAGE(D50,C50) -> 4827.09 | E51: =AVERAGE(E50,D50) -> 4829.14 | F51: =AVERAGE(F50,E50) -> 3887.39 | G51: =AVERAGE(G50,F50) -> 4299.295 | H51: =AVERAGE(H50,G50) -> 5103.735 | I51: =AVERAGE(I50,H50) -> 5104.72 | J51: =AVERAGE(J50,I50) -> 5904.1443 | K51: =AVERAGE(K50,J50) -> 7357.6989 | ... P51: =AVERAGE(P50,O50) -> 25812.626
B52: EBIT | C52: ='Income Statement'!C25+'Income Statement'!C19 -> 1777.02 | D52: ='Income Statement'!D25+'Income Statement'!D19 -> 1938.21 | E52: ='Income Statement'!E25+'Income Statement'!E19 -> 2625.12 | F52: ='Income Statement'!F25+'Income Statement'!F19 -> 2223.6 | G52: ='Income Statement'!G25+'Income Statement'!G19 -> 2826.27 | H52: ='Income Statement'!H25+'Income Statement'!H19 -> 3080.37 | I52: ='Income Statement'!I25+'Income Statement'!I19 -> 3090.16 | J52: ='Income Statement'!J25+'Income Statement'!J19 -> 4044.3812 | ... P52: ='Income Statement'!P25+'Income Statement'!P19 -> 13128.315
B53: EBITDA | C53: ='Income Statement'!C27+'Income Statement'!C20+'Income Statement'!C19 -> 1938.9 | D53: ='Income Statement'!D27+'Income Statement'!D20+'Income Statement'!D19 -> 2106.01 | E53: ='Income Statement'!E27+'Income Statement'!E20+'Income Statement'!E19 -> 2822.36 | F53: ='Income Statement'!F27+'Income Statement'!F20+'Income Statement'!F19 -> 2423.16 | G53: ='Income Statement'!G27+'Income Statement'!G20+'Income Statement'!G19 -> 3427.78 | H53: ='Income Statement'!H27+'Income Statement'!H20+'Income Statement'!H19 -> 3377.93 | I53: ='Income Statement'!I27+'Income Statement'!I20+'Income Statement'!I19 -> 3378.71 | J53: ='Income Statement'!J27+'Income Statement'!J20+'Income Statement'!J19 -> 3763.0501 | ... P53: ='Income Statement'!P27+'Income Statement'!P20+'Income Statement'!P19 -> 12799.516

Sheet Assumption Sheet
B1: Britannia Industries Limited
B2: ASSUMPTION SHEET
B4: Particulars | C4: 2019 | D4: 2020 | E4: 2021 | F4: 2022 | G4: 2023 | H4: 2024 | I4: 2025 | J4: 2026 | K4: 2027 | L4: 2028 | M4: 2029 | N4: 2030 | O4: 2031 | P4: 2032
C5: Actual | D5: Actual | E5: Actual | F5: Actual | G5: Actual | H5: Actual | I5: Actual | J5: Forecast | K5: Forecast | L5: Forecast | M5: Forecast | N5: Forecast | O5: Forecast | P5: Forecast
B6: Revenue Schedule(%)
B7: % change in Revenue | D7: ='Revenue Schedule'!D8 -> 0.049289576 | E7: ='Revenue Schedule'!E8 -> 0.13246979 | F7: ='Revenue Schedule'!F8 -> 0.076134999 | G7: ='Revenue Schedule'!G8 -> 0.15310202 | H7: ='Revenue Schedule'!H8 -> 0.028754858 | I7: ='Revenue Schedule'!I8 -> 0.069973231 | J7: ='Revenue Schedule'!J8 -> 0.076970554 | K7: ='Revenue Schedule'!K8 -> 0.084667609 | ... P7: ='Revenue Schedule'!P8 -> 0.13635803
B9: Cost Schedule (%)
B10: COGS | C10: ='Cost Schedule '!C15 -> 0.59354644 | D10: ='Cost Schedule '!D15 -> 0.59721886 | E10: ='Cost Schedule '!E15 -> 0.58054345 | F10: ='Cost Schedule '!F15 -> 0.61970422 | G10: ='Cost Schedule '!G15 -> 0.58840346 | H10: ='Cost Schedule '!H15 -> 0.56603716 | I10: ='Cost Schedule '!I15 -> 0.59099621 | J10: ='Cost Schedule '!J15 -> 0.58181228 | ... P10: ='Cost Schedule '!P15 -> 0.59
B12: Employee Expense | C12: ='Cost Schedule '!C25 -> 0.039966819 | D12: ='Cost Schedule '!D25 -> 0.041957662 | E12: ='Cost Schedule '!E25 -> 0.040147258 | F12: ='Cost Schedule '!F25 -> 0.03835951 | G12: ='Cost Schedule '!G25 -> 0.040390048 | H12: ='Cost Schedule '!H25 -> 0.042261828 | I12: ='Cost Schedule '!I25 -> 0.039268961 | J12: ='Cost Schedule '!J25 -> 0.040070086 | ... P12: ='Cost Schedule '!P25 -> 0.040336012
B14: Tax Expense | C14: ='Cost Schedule '!C33 -> 0.3464334 | D14: ='Cost Schedule '!D33 -> 0.24437456 | E14: ='Cost Schedule '!E33 -> 0.26377203 | F14: ='Cost Schedule '!F33 -> 0.27057782 | G14: ='Cost Schedule '!G33 -> 0.23623618 | H14: ='Cost Schedule '!H33 -> 0.26746457 | I14: ='Cost Schedule '!I33 -> 0.25583191 | J14: ='Cost Schedule '!J33 -> 0.25752762 | ... P14: ='Cost Schedule '!P33 -> 0.25752762
B16: Other Expenses | C16: ='Cost Schedule '!C29 -> 0.20968242 | D16: ='Cost Schedule '!D29 -> 0.20192249 | E16: ='Cost Schedule '!E29 -> 0.18828743 | F16: ='Cost Schedule '!F29 -> 0.1862013 | G16: ='Cost Schedule '!G29 -> 0.19753689 | H16: ='Cost Schedule '!H29 -> 0.2026743 | I16: ='Cost Schedule '!I29 -> 0.19210519 | J16: ='Cost Schedule '!J29 -> 0.19462942 | ... P16: ='Cost Schedule '!P29 -> 0.19462942
B18: Asset Schedule (%)
B19: Addition | C19: ='Asset Schedule'!C17 -> 0 | D19: ='Asset Schedule'!D17 -> 6.747985 | E19: ='Asset Schedule'!E17 -> 7.3849985 | F19: ='Asset Schedule'!F17 -> 7.9705115 | G19: ='Asset Schedule'!G17 -> 7.584191 | H19: ='Asset Schedule'!H17 -> 6.371158 | I19: ='Asset Schedule'!I17 -> 6.3427211 | J19: ='Asset Schedule'!J17 -> 7.0669275 | ... P19: ='Asset Schedule'!P17 -> 6.9831144
B21: Disposal | C21: ='Asset Schedule'!C23 -> 0 | D21: ='Asset Schedule'!D23 -> -0.00043997903 | E21: ='Asset Schedule'!E23 -> -0.001219951 | F21: ='Asset Schedule'!F23 -> -0.0017817171 | G21: ='Asset Schedule'!G23 -> -0.03649129 | H21: ='Asset Schedule'!H23 -> -0.024513119 | I21: ='Asset Schedule'!I23 -> -0.0016190267 | J21: ='Asset Schedule'!J23 -> -0.011010847 | ... P21: ='Asset Schedule'!P23 -> -0.013444118
B23: Depreciation | C23: ='Asset Schedule'!C28 -> 0 | D23: ='Asset Schedule'!D28 -> -0.19419547 | E23: ='Asset Schedule'!E28 -> -0.19581063 | F23: ='Asset Schedule'!F28 -> -0.17260032 | G23: ='Asset Schedule'!G28 -> -0.15793816 | H23: ='Asset Schedule'!H28 -> -0.18867605 | I23: ='Asset Schedule'!I28 -> -0.19561071 | J23: ='Asset Schedule'!J28 -> -0.18413856 | ... P23: ='Asset Schedule'!P28 -> -0.18311475
B25: Debt Schedule (%)
B26: New Borrowings | C26: ='Debt Schedule'!C20 -> 0 | D26: ='Debt Schedule'!D20 -> 0.062153273 | E26: ='Debt Schedule'!E20 -> 0 | F26: ='Debt Schedule'!F20 -> 0.049413353 | G26: ='Debt Schedule'!G20 -> 0 | H26: ='Debt Schedule'!H20 -> 0 | I26: ='Debt Schedule'!I20 -> 0 | J26: ='Debt Schedule'!J20 -> 0.015938089 | ... P26: ='Debt Schedule'!P20 -> 0.015938089
B28: Repayment | C28: ='Debt Schedule'!C26 -> 0 | D28: ='Debt Schedule'!D26 -> 0 | E28: ='Debt Schedule'!E26 -> 0 | F28: ='Debt Schedule'!F26 -> -0.023711133 | G28: ='Debt Schedule'!G26 -> -0.099336624 | H28: ='Debt Schedule'!H26 -> 0 | I28: ='Debt Schedule'!I26 -> 0 | J28: ='Debt Schedule'!J26 -> -0.02050796 | ... P28: ='Debt Schedule'!P26 -> -0.02050796
B30: Finance cost | C30: ='Debt Schedule'!C31 -> 0.13172004 | D30: ='Debt Schedule'!D31 -> 0.093095329 | E30: ='Debt Schedule'!E31 -> 0.061590239 | F30: ='Debt Schedule'!F31 -> 0.063386423 | G30: ='Debt Schedule'!G31 -> 0.062100054 | H30: ='Debt Schedule'!H31 -> 0.065316266 | I30: ='Debt Schedule'!I31 -> 0.084997459 | J30: ='Debt Schedule'!J31 -> 0.080315116 | ... P30: ='Debt Schedule'!P31 -> 0.080315116
B32: Working Capital Schedule (%)
B33: Inventory Turnover Ratio | D33: 9.1010812 | E33: 8.3233922 | F33: 7.1251495 | G33: 7.4910085 | H33: 7.9950389 | I33: 8.7719059 | J33: 8.134596 | K33: 7.9735152 | L33: 7.9152023 | M33: 8.0468778 | N33: 8.1395227 | O33: 8.1636033 | P33: 8.0622195
B35: Receivable Turnover Ratio | D35: 32.464456 | E35: 45.482887 | F35: 47.984589 | G35: 49.330579 | H35: 46.434907 | I35: 42.622206 | J35: 44.053271 | K35: 44.053271 | L35: 44.053271 | M35: 44.053271 | N35: 44.053271 | O35: 44.053271 | P35: 44.053271
B37: Payable Turnover Ratio | D37: 0.8902725 | E37: 0.98307611 | F37: 1.0324618 | G37: 0.96487253 | H37: 0.61208794 | I37: 0.47894642 | J37: 0.82695289 | K37: 0.82695289 | L37: 0.82695289 | M37: 0.82695289 | N37: 0.82695289 | O37: 0.82695289 | P37: 0.82695289

Sheet Revenue Schedule
B1: Britannia Industries Limited
B2: REVENUE SCHEDULE
B5: Particulars | C5: 2019 | D5: 2020 | E5: 2021 | F5: 2022 | G5: 2023 | H5: 2024 | I5: 2025 | J5: 2026 | K5: 2027 | L5: 2028 | M5: 2029 | N5: 2030 | O5: 2031 | P5: 2032
C6: Actual | D6: Actual | E6: Actual | F6: Actual | G6: Actual | H6: Actual | I6: Actual | J6: Forecast | K6: Forecast | L6: Forecast | M6: Forecast | N6: Forecast | O6: Forecast | P6: Forecast
B8: Revenue % Change : | D8: =D13/C13-1 -> 0.049289576 | E8: =E13/D13-1 -> 0.13246979 | F8: =F13/E13-1 -> 0.076134999 | G8: =G13/F13-1 -> 0.15310202 | H8: =H13/G13-1 -> 0.028754858 | I8: =I13/H13-1 -> 0.069973231 | J8: =I8+I8*10% -> 0.076970554 | K8: =J8+J8*10% -> 0.084667609 | L8: =K8+K8*10% -> 0.09313437 | M8: =L8+L8*10% -> 0.10244781 | N8: =M8+M8*10% -> 0.11269259 | O8: =N8+N8*10% -> 0.12396185 | P8: =O8+O8*10% -> 0.13635803
B10: Composition of revenue
B11: Revenue from sale of products | C11: ='Income Statement'!C8 -> 10973.46 | D11: ='Income Statement'!D8 -> 11443.99 | E11: ='Income Statement'!E8 -> 12883.04 | F11: ='Income Statement'!F8 -> 13944.67 | G11: ='Income Statement'!G8 -> 15984.9 | H11: 16546.21 | I11: 17535.02 | J11: =ROUND(J13*$J16,2) -> 19045.97 | K11: =ROUND(K13*$J16,2) -> 20658.55 | L11: =ROUND(L13*$J16,2) -> 22582.57 | M11: =ROUND(M13*$J16,2) -> 24896.1 | N11: =ROUND(N13*$J16,2) -> 27701.71 | O11: =ROUND(O13*$J16,2) -> 31135.66 | P11: =ROUND(P13*$J16,2) -> 35381.26
